<?xml version='1.0' encoding='utf-8'?>
<robot xmlns:xacro="http://www.ros.org/wiki/xacro" name="panda">
  <xacro:macro name="panda_arm" params="arm_id:='panda' description_pkg:='franka_description' connected_to:='' xyz:='0 0 0' rpy:='0 0 0'">
    <xacro:unless value="${not connected_to}">
      <joint name="${arm_id}_joint_${connected_to}" type="fixed">
        <parent link="${connected_to}"/>
        <child link="${arm_id}_link0"/>
        <origin rpy="${rpy}" xyz="${xyz}"/>
      </joint>
    </xacro:unless>

    <!-- Masses, COG and inertias -->
    <xacro:property name="link0_mass" value="3.06357" />
    <xacro:property name="link1_mass" value="2.34471" />
    <xacro:property name="link2_mass" value="2.36414" />
    <xacro:property name="link3_mass" value="2.38050" />
    <xacro:property name="link4_mass" value="2.42754" />
    <xacro:property name="link5_mass" value="3.49611" />
    <xacro:property name="link6_mass" value="1.46736" />
    <xacro:property name="link7_mass" value="0.45606" />
    <xacro:property name="link8_mass" value="0.001" /> --
    <xacro:property name="link0_cog" value="-0.029190 -0.000879 0.056603" />
    <xacro:property name="link1_cog" value="0.000011 -0.031266 -0.069373" />
    <xacro:property name="link2_cog" value="-0.000013 -0.070322 0.031178" />
    <xacro:property name="link3_cog" value="0.044348 0.024928 -0.038130" />
    <xacro:property name="link4_cog" value="-0.038550 0.039526 0.024716" />
    <xacro:property name="link5_cog" value="-0.000064 0.038412 -0.109970" />
    <xacro:property name="link6_cog" value="0.051002 0.006933 0.006169" />
    <xacro:property name="link7_cog" value="0.010361 0.010360 0.079108" />
    <xacro:property name="link8_cog" value="0.0 0.0 0.0" />

    <!-- for simulation -->
    <link name="world" />

    <joint name="robot_to_world" type="fixed">
      <parent link="world" />
      <child link="${arm_id}_link0" />
      <origin xyz="0.0 0.0 0.0" rpy="0.0 0.0 0.0" />
    </joint>

    <xacro:property name="joint_damping" value="1.0"/>
    <!-- end for simulation -->

    <link name="${arm_id}_link0">
      <visual>
        <geometry>
          <mesh filename="package://${description_pkg}/meshes/visual/link0.dae"/>
        </geometry>
      </visual>
      <collision>
        <geometry>
          <mesh filename="package://${description_pkg}/meshes/collision/link0.stl"/>
        </geometry>
      </collision>

      <!-- for simulation -->
      <inertial>
        <origin xyz="${link0_cog}" rpy="0 0 0" />
        <mass value="${link0_mass}" />
        <inertia ixx="0.009" iyy="0.0122" izz="0.0122" ixy="0.0" ixz="-0.00010" iyz="0.0" />
      </inertial>
      <!-- end for simulation -->
    </link>
    <link name="${arm_id}_link1">
      <visual>
        <geometry>
          <mesh filename="package://${description_pkg}/meshes/visual/link1.dae"/>
        </geometry>
      </visual>
      <collision>
        <geometry>
          <mesh filename="package://${description_pkg}/meshes/collision/link1.stl"/>
        </geometry>
      </collision>

      <!-- for simulation -->
      <inertial>
        <origin xyz="${link1_cog}" rpy="0 0 0" />
        <mass value="${link1_mass}" />
        <inertia ixx="0.01418" iyy="0.01181" izz="0.005515" ixy="0.0" ixz="0.0" iyz="0.00236" />
      </inertial>
      <!-- end for simulation -->
    </link>
    <joint name="${arm_id}_joint1" type="revolute">
      <safety_controller k_position="100.0" k_velocity="40.0" soft_lower_limit="-2.8973" soft_upper_limit="2.8973"/>
      <origin rpy="0 0 0" xyz="0 0 0.333"/>
      <parent link="${arm_id}_link0"/>
      <child link="${arm_id}_link1"/>
      <axis xyz="0 0 1"/>
      <limit effort="87" lower="-2.8973" upper="2.8973" velocity="2.1750"/>

      <!-- for simulation -->
      <dynamics damping="${joint_damping}"/>
      <!-- end for simulation -->
    </joint>
    <link name="${arm_id}_link2">
      <visual>
        <geometry>
          <mesh filename="package://${description_pkg}/meshes/visual/link2.dae"/>
        </geometry>
      </visual>
      <collision>
        <geometry>
          <mesh filename="package://${description_pkg}/meshes/collision/link2.stl"/>
        </geometry>
      </collision>

      <!-- for simulation -->
      <inertial>
        <origin xyz="${link2_cog}" rpy="0 0 0" />
        <mass value="${link2_mass}" />
        <inertia ixx="0.014" ixy="0.0" ixz="0.0" iyy="0.0055" iyz="-0.0023" izz="0.01259" />
      </inertial>
      <!-- end for simulation -->
    </link>
    <joint name="${arm_id}_joint2" type="revolute">
      <safety_controller k_position="100.0" k_velocity="40.0" soft_lower_limit="-1.7628" soft_upper_limit="1.7628"/>
      <origin rpy="${-pi/2} 0 0" xyz="0 0 0"/>
      <parent link="${arm_id}_link1"/>
      <child link="${arm_id}_link2"/>
      <axis xyz="0 0 1"/>
      <limit effort="87" lower="-1.7628" upper="1.7628" velocity="2.1750"/>

      <!-- for simulation -->
      <dynamics damping="${joint_damping}"/>
      <!-- end for simulation -->
    </joint>
    <link name="${arm_id}_link3">
      <visual>
        <geometry>
          <mesh filename="package://${description_pkg}/meshes/visual/link3.dae"/>
        </geometry>
      </visual>
      <collision>
        <geometry>
          <mesh filename="package://${description_pkg}/meshes/collision/link3.stl"/>
        </geometry>
      </collision>

      <!-- for simulation -->
      <inertial>
        <origin xyz="${link3_cog}" rpy="0 0 0" />
        <mass value="${link3_mass}" />
        <inertia ixx="0.00716" ixy="-0.00102" ixz="-0.02040" iyy="0.00920" iyz="-0.00102" izz="0.007159" />
      </inertial>
      <!-- end for simulation -->
    </link>
    <joint name="${arm_id}_joint3" type="revolute">
      <safety_controller k_position="100.0" k_velocity="40.0" soft_lower_limit="-2.8973" soft_upper_limit="2.8973"/>
      <origin rpy="${pi/2} 0 0" xyz="0 -0.316 0"/>
      <parent link="${arm_id}_link2"/>
      <child link="${arm_id}_link3"/>
      <axis xyz="0 0 1"/>
      <limit effort="87" lower="-2.8973" upper="2.8973" velocity="2.1750"/>

      <!-- for simulation -->
      <dynamics damping="${joint_damping}"/>
      <!-- end for simulation -->
    </joint>
    <link name="${arm_id}_link4">
      <visual>
        <geometry>
          <mesh filename="package://${description_pkg}/meshes/visual/link4.dae"/>
        </geometry>
      </visual>
      <collision>
        <geometry>
          <mesh filename="package://${description_pkg}/meshes/collision/link4.stl"/>
        </geometry>
      </collision>

      <!-- for simulation -->
      <inertial>
        <origin xyz="${link4_cog}" rpy="0 0 0" />
        <mass value="${link4_mass}" />
        <inertia ixx="0.008164" ixy="0.003061" ixz="0.00102" iyy="0.008165" iyz="0.00102" izz="0.009185" />
      </inertial>
      <!-- end for simulation -->
    </link>
    <joint name="${arm_id}_joint4" type="revolute">
      <safety_controller k_position="100.0" k_velocity="40.0" soft_lower_limit="-3.0718" soft_upper_limit="-0.0698"/>
      <origin rpy="${pi/2} 0 0" xyz="0.0825 0 0"/>
      <parent link="${arm_id}_link3"/>
      <child link="${arm_id}_link4"/>
      <axis xyz="0 0 1"/>
      <limit effort="87" lower="-3.0718" upper="-0.0698" velocity="2.1750"/>

      <!-- for simulation -->
      <dynamics damping="${joint_damping}"/>
      <!-- end for simulation -->
    </joint>
    <link name="${arm_id}_link5">
      <visual>
        <geometry>
          <mesh filename="package://${description_pkg}/meshes/visual/link5.dae"/>
        </geometry>
      </visual>
      <collision>
        <geometry>
          <mesh filename="package://${description_pkg}/meshes/collision/link5.stl"/>
        </geometry>
      </collision>

      <!-- for simulation -->
      <inertial>
        <origin xyz="${link5_cog}" rpy="0 0 0" />
        <mass value="${link5_mass}" />
        <inertia ixx="0.0307" ixy="0.0" ixz="0.0" iyy="0.02761" iyz="-0.0613" izz="0.00818" />
      </inertial>
      <!-- end for simulation -->
    </link>
    <joint name="${arm_id}_joint5" type="revolute">
      <safety_controller k_position="100.0" k_velocity="40.0" soft_lower_limit="-2.8973" soft_upper_limit="2.8973"/>
      <origin rpy="${-pi/2} 0 0" xyz="-0.0825 0.384 0"/>
      <parent link="${arm_id}_link4"/>
      <child link="${arm_id}_link5"/>
      <axis xyz="0 0 1"/>
      <limit effort="12" lower="-2.8973" upper="2.8973" velocity="2.6100"/>

      <!-- for simulation -->
      <dynamics damping="${joint_damping}"/>
      <!-- end for simulation -->
    </joint>
    <link name="${arm_id}_link6">
      <visual>
        <geometry>
          <mesh filename="package://${description_pkg}/meshes/visual/link6.dae"/>
        </geometry>
      </visual>
      <collision>
        <geometry>
          <mesh filename="package://${description_pkg}/meshes/collision/link6.stl"/>
        </geometry>
      </collision>

      <!-- for simulation -->
      <inertial>
        <origin xyz="${link6_cog}" rpy="0 0 0" />
        <mass value="${link6_mass}" />
        <inertia ixx="0.00205" ixy="0.0" ixz="0.0" iyy="0.004089" iyz="0" izz="0.00490" />
      </inertial>
      <!-- end for simulation -->
    </link>
    <joint name="${arm_id}_joint6" type="revolute">
      <safety_controller k_position="100.0" k_velocity="40.0" soft_lower_limit="-0.0175" soft_upper_limit="3.7525"/>
      <origin rpy="${pi/2} 0 0" xyz="0 0 0"/>
      <parent link="${arm_id}_link5"/>
      <child link="${arm_id}_link6"/>
      <axis xyz="0 0 1"/>
      <limit effort="12" lower="-0.0175" upper="3.7525" velocity="2.6100"/>

      <!-- for simulation -->
      <dynamics damping="${joint_damping}"/>
      <!-- end for simulation -->
    </joint>
    <link name="${arm_id}_link7">
      <visual>
        <geometry>
          <mesh filename="package://${description_pkg}/meshes/visual/link7.dae"/>
        </geometry>
      </visual>
      <collision>
        <geometry>
          <mesh filename="package://${description_pkg}/meshes/collision/link7.stl"/>
        </geometry>
      </collision>

      <!-- for simulation -->
      <inertial>
        <origin xyz="${link7_cog}" rpy="0 0 0" />
        <mass value="${link7_mass}" />
        <inertia ixx="0.3" ixy="0.0" ixz="0.0" iyy="0.3" iyz="0.0" izz="0.3" />
      </inertial>
      <!-- end for simulation -->
    </link>
    <joint name="${arm_id}_joint7" type="revolute">
      <safety_controller k_position="100.0" k_velocity="40.0" soft_lower_limit="-2.8973" soft_upper_limit="2.8973"/>
      <origin rpy="${pi/2} 0 0" xyz="0.088 0 0"/>
      <parent link="${arm_id}_link6"/>
      <child link="${arm_id}_link7"/>
      <axis xyz="0 0 1"/>
      <limit effort="12" lower="-2.8973" upper="2.8973" velocity="2.6100"/>

      <!-- for simulation -->
      <dynamics damping="${joint_damping}"/>
      <!-- end for simulation -->
    </joint>
    <link name="${arm_id}_link8">
      <!-- for simulation -->
      <inertial>
        <origin xyz="${link8_cog}" rpy="0 0 0" />
        <mass value="${link8_mass}" />
        <inertia ixx="0.3" ixy="0.0" ixz="0.0" iyy="0.3" iyz="0.0" izz="0.3" />
      </inertial>
      <!-- end for simulation -->
    </link>
    <joint name="${arm_id}_joint8" type="fixed">
      <origin rpy="0 0 0" xyz="0 0 0.107"/>
      <parent link="${arm_id}_link7"/>
      <child link="${arm_id}_link8"/>
      <axis xyz="0 0 0"/>
    </joint>
  </xacro:macro>
</robot>
